Workbook

Sheet NPT 011 - Anexo A - Tabela 1
A1: Ocupação | F1: Capacidade da U. de passagem
A2: Grupo | B2: Divisão (E) (F) (M)* (N) (P) (Q) | D2: População (A) | E2: População | F2: Acessos e descargas | G2: Escadas e rampas (B) | H2: Portas
A3: A | B3: A-1, A-2 | C3: A-1 | D3: Duas pessoas por dormitório (C) | E3: 0 | F3: 60 | G3: 45 | H3: 100
B4: A-1, A-2 | C4: A-2 | D4: Duas pessoas por dormitório (C) | E4: 0 | F4: 60 | G4: 45 | H4: 100
B5: A-3 | C5: A-3 | D5: Duas pessoas por dormitório e uma pessoa por 4,0 m² de área de alojamento (D) | E5: 0 | F5: 60 | G5: 45 | H5: 100
A6: B | B6: - | C6: B-1 | D6: Uma pessoa por 15,0 m² de área | E6: 15 | F6: 60 | G6: 45 | H6: 100
B7: - | C7: B-2 | D7: Uma pessoa por 15,0 m² de área | E7: 15 | F7: 60 | G7: 45 | H7: 100
A8: C | B8: - | C8: C-1 | D8: Uma pessoa por 5,0 m² de área (I) (L) | E8: 5 | F8: 100 | G8: 75 | H8: 100
B9: - | C9: C-2 | D9: Uma pessoa por 5,0 m² de área (I) (L) | E9: 5 | F9: 100 | G9: 75 | H9: 100
B10: - | C10: C-3 | D10: Uma pessoa por 5,0 m² de área (I) (L) | E10: 5 | F10: 100 | G10: 75 | H10: 100
A11: D | B11: D-1 (K), D-2, D-3, D-4 | C11: D-1 | D11: Uma pessoa por 7,0 m² de área | E11: 7 | F11: 100 | G11: 75 | H11: 100
C12: D-2 | D12: Uma pessoa por 7,0 m² de área | E12: 7 | F12: 100 | G12: 75 | H12: 100
C13: D-3 | D13: Uma pessoa por 7,0 m² de área | E13: 7 | F13: 100 | G13: 75 | H13: 100
C14: D-4 | D14: Uma pessoa por 7,0 m² de área | E14: 7 | F14: 100 | G14: 75 | H14: 100
A15: E | B15: E-1 a E-4 | C15: E-1 | D15: Uma pessoa por 1,50 m² de área de sala de aula | E15: 1.5 | F15: 100 | G15: 75 | H15: 100
C16: E-2 | D16: Uma pessoa por 1,50 m² de área de sala de aula | E16: 1.5 | F16: 100 | G16: 75 | H16: 100
C17: E-3 | D17: Uma pessoa por 1,50 m² de área de sala de aula | E17: 1.5 | F17: 100 | G17: 75 | H17: 100
C18: E-4 | D18: Uma pessoa por 1,50 m² de área de sala de aula | E18: 1.5 | F18: 100 | G18: 75 | H18: 100
B19: E-5, E-6 | C19: E-5 | D19: Uma pessoa por 1,50 m² de área de sala de aula | E19: 1.5 | F19: 30 | G19: 22 | H19: 30
C20: E-6 | D20: Uma pessoa por 1,50 m² de área de sala de aula | E20: 1.5 | F20: 30 | G20: 22 | H20: 30
A21: F | B21: F-1, F-10 | C21: F-1 | D21: Uma pessoa por 3,0 m² de área | E21: 3 | F21: 100 | G21: 75 | H21: 100
C22: F-10 | D22: Uma pessoa por 3,0 m² de área | E22: 3 | F22: 100 | G22: 75 | H22: 100
C23: F-2 | D23: Uma pessoa por 1,0 m² de área (O) | E23: 1 | F23: 100 | G23: 75 | H23: 100
C24: F-5 | D24: Uma pessoa por 1,0 m² de área (O) | E24: 1 | F24: 100 | G24: 75 | H24: 100
B25: F-2, F-5, F8 | C25: F-8 | D25: Uma pessoa por 1,0 m² de área (O) | E25: 1 | F25: 100 | G25: 75 | H25: 100
B26: F-3(J) (O), F-6(O), F-7(J) (O), F-9(O),F-11(O) | C26: F-3 | D26: Duas pessoas por 1,0 m² de área (1:0,5 m2) | E26: 0.5 | F26: 100 | G26: 75 | H26: 100
C27: F-6 | D27: Duas pessoas por 1,0 m² de área (1:0,5 m2) | E27: 0.5 | F27: 100 | G27: 75 | H27: 100
C28: F-7 | D28: Duas pessoas por 1,0 m² de área (1:0,5 m2) | E28: 0.5 | F28: 100 | G28: 75 | H28: 100
C29: F-9 | D29: Duas pessoas por 1,0 m² de área (1:0,5 m2) | E29: 0.5 | F29: 100 | G29: 75 | H29: 100
C30: F-11 | D30: Duas pessoas por 1,0 m² de área (1:0,5 m2) | E30: 0.5 | F30: 100 | G30: 75 | H30: 100
B31: F-4 | C31: F-4 | D31: Uma pessoa por 3,0 m² de área | E31: 3 | F31: 100 | G31: 75 | H31: 100
A32: G | B32: G-1, G-2, G3 | C32: G-1 | D32: Uma pessoa por 40 vagas de veículo | E32: 40 | F32: 100 | G32: 60 | H32: 100
C33: G-2 | D33: Uma pessoa por 40 vagas de veículo | E33: 40 | F33: 100 | G33: 60 | H33: 100
C34: G-3 | D34: Uma pessoa por 40 vagas de veículo | E34: 40 | F34: 100 | G34: 60 | H34: 100
B35: G-4, G-5 | C35: G-4 | D35: Uma pessoa por 20,0 m² de área | E35: 20 | F35: 100 | G35: 60 | H35: 100
C36: G-5 | D36: Uma pessoa por 20,0 m² de área | E36: 20 | F36: 100 | G36: 60 | H36: 100
A37: H | B37: H-1, H-6 | C37: H-1 | D37: Uma pessoa por 7,0 m² de área | E37: 7 | F37: 60 | G37: 45 | H37: 100
C38: H-6 | D38: Uma pessoa por 7,0 m² de área | E38: 7 | F38: 60 | G38: 45 | H38: 100
B39: H-2 | C39: H-2 | D39: Duas pessoas por dormitório (C) e uma pessoa por 4,0 m² de área de alojamento | E39: 0 | F39: 30 | G39: 22 | H39: 30
B40: H-3 | C40: H-3 | D40: Uma pessoa e meia por leito + uma pessoa por 7,0 m² de área de ambulatório (G) | E40: 0 | F40: 30 | G40: 22 | H40: 30
...

Sheet CÁLCULO DETERMINÍSTICO
B1: INSTRUÇÕES:
B2: ESSE CÁLCULO É UTILIZADO EM DEPÓSITOS E SILOS E DEVE SER VINCULADO NA ABA "CÁLCULO PROBABILISTICO"
B3: VERIFICAR AS FÓRMULAS DAS CÉLULAS COM AS OUTRAS ABAS E AJUSTAR SE NECESSÁRIO.
B5: Tipo do material existente na edificação por compartimento | D5: Massa total de cada material Mi - (kg) | E5: Potencial calorífico específico Hi - (MJ/kg) | F5: Potencial calorífico por material Mi x Hi = qi (MJ) | G5: Área do piso do pavimento - Af (m²) | H5: Carga de incêndio específica do pavimento qfi = ΣMiHi/Af (MJ/m²)
B6: 1 | C6: Borracha em tiras | D6: 3000 | E6: 32 | F6: =D6*E6 -> 96000 | G6: ='CÁLCULO PROBABILÍSTICO'!F7 -> 56.67 | H6: =F6/G6 -> 1694.018
B7: 2 | C7: Madeira | D7: 3000 | E7: 19 | F7: =D7*E7 -> 57000 | G7: ='CÁLCULO PROBABILÍSTICO'!F6 -> 158 | H7: =F7/G7 -> 360.75949

Sheet CÁLCULO PROBABILÍSTICO
B1: INSTRUÇÕES:
B2: VERIFICAR AS FÓRMULAS DAS CÉLULAS COM AS OUTRAS ABAS E AJUSTAR SE NECESSÁRIO.
B3: Utilizar o campo observação quando precisar descrever sobre o cálculo da carga de incêndio em depósitos, indicando a altura considerada no cálculo e/ou potencial calorifico.
B5: Local | C5: Descrição | D5: Área Existente (m²) | E5: Área Ampliada (m²) | F5: Área computada (m²) | G5: Ocupação | H5: Carga de incêndio (MJ/m ²) | I5: Observação | J5: Tabela utilizada no dimensionamento | K5: Distância máxima a ser percorrida - Extintores (m) | L5: Tipo de Hidrante | N5: Medidas Necessárias
B6: 1º Pavimento | C6: Estocagem de Pinus | D6: 158 | E6: 0 | F6: =D6+E6 -> 158 | G6: J-3 | H6: ='CÁLCULO DETERMINÍSTICO'!H7 -> 360.75949 | J6: Tabela 5 | K6: =20*0.7 -> 14 | L6: Sem Hidrante | N6: Acesso de Viatura na Edificação
C7: Estocagem de Borracha | D7: 56.67 | E7: 0 | F7: =D7+E7 -> 56.67 | G7: J-4 | H7: ='CÁLCULO DETERMINÍSTICO'!H6 -> 1694.018 | J7: Tabela 5 | K7: =15*0.7 -> 10.5 | L7: Sem Hidrante | N7: Segurança Estrutural contra Incêndio
C8: Produção | D8: 182 | E8: 0 | F8: =D8+E8 -> 182 | G8: I-2 | H8: 800 | J8: Tabela 5 | K8: =20*0.7 -> 14 | L8: Sem Hidrante | N8: Compartimentação Horizontal
C9: Oficina | D9: 37.15 | E9: 0 | F9: =D9+E9 -> 37.15 | G9: G-4 | H9: 300 | J9: Tabela 5 | K9: =25*0.7 -> 17.5 | L9: Sem Hidrante | N9: Controle de Materiais e Acabamento
C10: Refeitório | D10: 29.25 | E10: 0 | F10: =D10+E10 -> 29.25 | G10: F-8 | H10: 300 | J10: Tabela 5 | K10: =25*0.7 -> 17.5 | L10: Sem Hidrante | N10: Saídas de Emergência
B11: TOTAL | D11: =SUM(D2:D10) -> 463.07 | E11: 0 | F11: =D11+E11 -> 463.07 | G11: - | H11: =SUMPRODUCT(F6:F10,H6:H10)/F11 -> 687.84417 | N11: Plano de Emergência
N12: Brigada de Incêndio
N13: Iluminação de Emergência
N14: Alarme de Incêndio
N15: Sinalização de Emergência
N16: Extintores
N17: Hidrante

Sheet SAIDAS DE EMERGÊNCIA
B1: INSTRUÇÕES:
B2: OBS 1: NA OCUPAÇÃO "TOTAL" DEVE SER PREENCHIDO COM A OCUPAÇÃO COM MENOR CAPACIDADE DE UNIDADE DE PASSAGEM DO PAVIMENTO. ESSA OCUPAÇÃO DEVE SER DEIXADA COM A COR DE LETRA "BRANCA" E A CÉLULA SEM PREENCHIMENTO PARA NÃO APARECER NO WORD. Ela está atualmente amarela apenas para destacar a observação e para entendimento da instrução.
B5: OBS2: A OCUPAÇÃO PARA O CÁLCULO DA POPULAÇÃO NÃO PRECISA SER A MESMA OCUPAÇÃO PARA O CÁLCULO DA CARGA DE INCÊNDIO. POR EXEMPLO, SE UMA LOJA TIVER UM DEPÓSTO PEQUENO NA MESMA EDIFICAÇAO, PARA A CARGA DE INCÊNDIO, O DEPÓSITO SERÁ UMA OCUPAÇÃO SUBSIDIÁRIA E TERÁ A MESMA CARGA DE INCÊNDIO A LOJA (C-2).
B8: OBS3: PARA O CÁLCULO DAS SAÍDAS DE EMERGÊNCIA, TERÁ OCUPAÇÃO DE DE DEPÓSITO (J-4). O CÁLCULO DA POPULAÇÃO DEVERÁ SER PREENCHIDO COM AS ÁREAS QUE DE FATO TEM OCUPAÇÃO (não precisa considerar banheiros, corredores, entre outros).
B11: OBS4: QUANDO FOR EDIFICAÇÃO EXISTENTE E FOR NECESSÁRIO LIMITAR A POPULAÇÃO PELAS LARGURAS EXISTENTES, DEVE SER COLOCADA UMA LINHA EXTRA INDICATIVA DA POPULAÇÃO MÁXIMA, CONFORME TABELA EXEMPLO QUE ESTÁ NO MEMORIAL DESCRITIVO EXEMPLO
B14: DADOS DA EDIFICAÇÃO | F14: POPULAÇÃO | H14: SAÍDAS DE EMERGÊNCIA
H15: Distância máxima a percorrer (m) | I15: Acessos e descargas | L15: Escadas de rampas | O15: Portas
B16: Local | C16: Descrição | D16: Área | E16: Ocupação | F16: Indice de Cálculo da População | G16: População Total | I16: Cap. da U.P. | J16: Nº U.P. | K16: Larg. Min. (m) | L16: Cap. da U.P. | M16: Nº U.P. | N16: Larg. Min. (m) | O16: Cap. da U.P. | P16: Nº U.P. | Q16: Larg. Min. (m)
B17: 1º Pavimento | C17: Estocagem de Pinus | D17: ='CÁLCULO PROBABILÍSTICO'!F6 -> 158 | E17: J-3 | F17: =VLOOKUP(E17,'NPT 011 - Anexo A - Tabela 1'!$C$3:$H$56,2,FALSE) -> Uma pessoa por 30,0 m² de área (I) | G17: =ROUNDUP(IF(VLOOKUP(E17,'NPT 011 - Anexo A - Tabela 1'!$C$3:$E$56,3,FALSE)=0,"Ver índice de cálculo",D17/VLOOKUP(E17,'NPT 011 - Anexo A - Tabela 1'!$C$3:$E$56,3,FALSE)),0) -> 6 | H17: 35 | I17: =VLOOKUP(E17,'NPT 011 - Anexo A - Tabela 1'!$C$3:$H$56,4,FALSE) -> 100 | J17: =ROUNDUP((G17/I17),0) -> 1 | K17: =IF(J17*0.55>1.2,J17*0.55,1.2) -> 1.2 | L17: =VLOOKUP(E17,'NPT 011 - Anexo A - Tabela 1'!$C$3:$H$56,5,FALSE) -> 60 | M17: =ROUNDUP((G17/L17),0) -> 1 | N17: =IF(M17*0.55>1.2,M17*0.55,1.2) -> 1.2 | O17: =VLOOKUP(E17,'NPT 011 - Anexo A - Tabela 1'!$C$3:$H$56,6,FALSE) -> 100 | P17: =ROUNDUP((G17/O17),0) -> 1 | Q17: =IF(P17*0.55>0.8,P17*0.55,0.8) -> 0.8
C18: Estocagem de Borracha | D18: ='CÁLCULO PROBABILÍSTICO'!F7 -> 56.67 | E18: J-3 | F18: =VLOOKUP(E18,'NPT 011 - Anexo A - Tabela 1'!$C$3:$H$56,2,FALSE) -> Uma pessoa por 30,0 m² de área (I) | G18: =ROUNDUP(IF(VLOOKUP(E18,'NPT 011 - Anexo A - Tabela 1'!$C$3:$E$56,3,FALSE)=0,"Ver índice de cálculo",D18/VLOOKUP(E18,'NPT 011 - Anexo A - Tabela 1'!$C$3:$E$56,3,FALSE)),0) -> 2 | H18: 35 | I18: =VLOOKUP(E18,'NPT 011 - Anexo A - Tabela 1'!$C$3:$H$56,4,FALSE) -> 100 | J18: =ROUNDUP((G18/I18),0) -> 1 | K18: =IF(J18*0.55>1.2,J18*0.55,1.2) -> 1.2 | L18: =VLOOKUP(E18,'NPT 011 - Anexo A - Tabela 1'!$C$3:$H$56,5,FALSE) -> 60 | M18: =ROUNDUP((G18/L18),0) -> 1 | N18: =IF(M18*0.55>1.2,M18*0.55,1.2) -> 1.2 | O18: =VLOOKUP(E18,'NPT 011 - Anexo A - Tabela 1'!$C$3:$H$56,6,FALSE) -> 100 | P18: =ROUNDUP((G18/O18),0) -> 1 | Q18: =IF(P18*0.55>0.8,P18*0.55,0.8) -> 0.8
C19: Produção | D19: ='CÁLCULO PROBABILÍSTICO'!F8 -> 182 | E19: I-2 | F19: =VLOOKUP(E19,'NPT 011 - Anexo A - Tabela 1'!$C$3:$H$56,2,FALSE) -> Uma pessoa por 10,0 m² de área | G19: =ROUNDUP(IF(VLOOKUP(E19,'NPT 011 - Anexo A - Tabela 1'!$C$3:$E$56,3,FALSE)=0,"Ver índice de cálculo",D19/VLOOKUP(E19,'NPT 011 - Anexo A - Tabela 1'!$C$3:$E$56,3,FALSE)),0) -> 19 | H19: 35 | I19: =VLOOKUP(E19,'NPT 011 - Anexo A - Tabela 1'!$C$3:$H$56,4,FALSE) -> 100 | J19: =ROUNDUP((G19/I19),0) -> 1 | K19: =IF(J19*0.55>1.2,J19*0.55,1.2) -> 1.2 | L19: =VLOOKUP(E19,'NPT 011 - Anexo A - Tabela 1'!$C$3:$H$56,5,FALSE) -> 60 | M19: =ROUNDUP((G19/L19),0) -> 1 | N19: =IF(M19*0.55>1.2,M19*0.55,1.2) -> 1.2 | O19: =VLOOKUP(E19,'NPT 011 - Anexo A - Tabela 1'!$C$3:$H$56,6,FALSE) -> 100 | P19: =ROUNDUP((G19/O19),0) -> 1 | Q19: =IF(P19*0.55>0.8,P19*0.55,0.8) -> 0.8
C20: Oficina | D20: ='CÁLCULO PROBABILÍSTICO'!F9 -> 37.15 | E20: G-4 | F20: =VLOOKUP(E20,'NPT 011 - Anexo A - Tabela 1'!$C$3:$H$56,2,FALSE) -> Uma pessoa por 20,0 m² de área | G20: =ROUNDUP(IF(VLOOKUP(E20,'NPT 011 - Anexo A - Tabela 1'!$C$3:$E$56,3,FALSE)=0,"Ver índice de cálculo",D20/VLOOKUP(E20,'NPT 011 - Anexo A - Tabela 1'!$C$3:$E$56,3,FALSE)),0) -> 2 | H20: 28 | I20: =VLOOKUP(E20,'NPT 011 - Anexo A - Tabela 1'!$C$3:$H$56,4,FALSE) -> 100 | J20: =ROUNDUP((G20/I20),0) -> 1 | K20: =IF(J20*0.55>1.2,J20*0.55,1.2) -> 1.2 | L20: =VLOOKUP(E20,'NPT 011 - Anexo A - Tabela 1'!$C$3:$H$56,5,FALSE) -> 60 | M20: =ROUNDUP((G20/L20),0) -> 1 | N20: =IF(M20*0.55>1.2,M20*0.55,1.2) -> 1.2 | O20: =VLOOKUP(E20,'NPT 011 - Anexo A - Tabela 1'!$C$3:$H$56,6,FALSE) -> 100 | P20: =ROUNDUP((G20/O20),0) -> 1 | Q20: =IF(P20*0.55>0.8,P20*0.55,0.8) -> 0.8
C21: Refeitório | D21: ='CÁLCULO PROBABILÍSTICO'!F10 -> 29.25 | E21: F-8 | F21: =VLOOKUP(E21,'NPT 011 - Anexo A - Tabela 1'!$C$3:$H$56,2,FALSE) -> Uma pessoa por 1,0 m² de área (O) | G21: =ROUNDUP(IF(VLOOKUP(E21,'NPT 011 - Anexo A - Tabela 1'!$C$3:$E$56,3,FALSE)=0,"Ver índice de cálculo",D21/VLOOKUP(E21,'NPT 011 - Anexo A - Tabela 1'!$C$3:$E$56,3,FALSE)),0) -> 30 | H21: 28 | I21: =VLOOKUP(E21,'NPT 011 - Anexo A - Tabela 1'!$C$3:$H$56,4,FALSE) -> 100 | J21: =ROUNDUP((G21/I21),0) -> 1 | K21: =IF(J21*0.55>1.2,J21*0.55,1.2) -> 1.2 | L21: =VLOOKUP(E21,'NPT 011 - Anexo A - Tabela 1'!$C$3:$H$56,5,FALSE) -> 75 | M21: =ROUNDUP((G21/L21),0) -> 1 | N21: =IF(M21*0.55>1.2,M21*0.55,1.2) -> 1.2 | O21: =VLOOKUP(E21,'NPT 011 - Anexo A - Tabela 1'!$C$3:$H$56,6,FALSE) -> 100 | P21: =ROUNDUP((G21/O21),0) -> 1 | Q21: =IF(P21*0.55>0.8,P21*0.55,0.8) -> 0.8
C22: TOTAL | E22: I-2 | F22: - | G22: =SUM(G17:G21) -> 59 | H22: - | I22: =VLOOKUP(E22,'NPT 011 - Anexo A - Tabela 1'!$C$3:$H$56,4,FALSE) -> 100 | J22: =ROUNDUP((G22/I22),0) -> 1 | K22: =IF(J22*0.55>1.2,J22*0.55,1.2) -> 1.2 | L22: =VLOOKUP(E22,'NPT 011 - Anexo A - Tabela 1'!$C$3:$H$56,5,FALSE) -> 60 | M22: =ROUNDUP((G22/L22),0) -> 1 | N22: =IF(M22*0.55>1.2,M22*0.55,1.2) -> 1.2 | O22: =VLOOKUP(E22,'NPT 011 - Anexo A - Tabela 1'!$C$3:$H$56,6,FALSE) -> 100 | P22: =ROUNDUP((G22/O22),0) -> 1 | Q22: =IF(P22*0.55>0.8,P22*0.55,0.8) -> 0.8
B23: 2º Pavimento | C23: Estocagem de Pinus | D23: 158 | E23: J-3 | F23: =VLOOKUP(E23,'NPT 011 - Anexo A - Tabela 1'!$C$9:$H$62,2,FALSE) -> Uma pessoa por 30,0 m² de área (I) | G23: =ROUNDUP(IF(VLOOKUP(E23,'NPT 011 - Anexo A - Tabela 1'!$C$3:$E$56,3,FALSE)=0,"Ver índice de cálculo",D23/VLOOKUP(E23,'NPT 011 - Anexo A - Tabela 1'!$C$3:$E$56,3,FALSE)),0) -> 6 | H23: 35 | I23: =VLOOKUP(E23,'NPT 011 - Anexo A - Tabela 1'!$C$3:$H$56,4,FALSE) -> 100 | J23: =ROUNDUP((G23/I23),0) -> 1 | K23: =IF(J23*0.55>1.2,J23*0.55,1.2) -> 1.2 | L23: =VLOOKUP(E23,'NPT 011 - Anexo A - Tabela 1'!$C$3:$H$56,5,FALSE) -> 60 | M23: =ROUNDUP((G23/L23),0) -> 1 | N23: =IF(M23*0.55>1.2,M23*0.55,1.2) -> 1.2 | O23: =VLOOKUP(E23,'NPT 011 - Anexo A - Tabela 1'!$C$3:$H$56,6,FALSE) -> 100 | P23: =ROUNDUP((G23/O23),0) -> 1 | Q23: =IF(P23*0.55>0.8,P23*0.55,0.8) -> 0.8
C24: Estocagem de Borracha | D24: 56.67 | E24: J-3 | F24: =VLOOKUP(E24,'NPT 011 - Anexo A - Tabela 1'!$C$9:$H$62,2,FALSE) -> Uma pessoa por 30,0 m² de área (I) | G24: =ROUNDUP(IF(VLOOKUP(E24,'NPT 011 - Anexo A - Tabela 1'!$C$3:$E$56,3,FALSE)=0,"Ver índice de cálculo",D24/VLOOKUP(E24,'NPT 011 - Anexo A - Tabela 1'!$C$3:$E$56,3,FALSE)),0) -> 2 | H24: 35 | I24: =VLOOKUP(E24,'NPT 011 - Anexo A - Tabela 1'!$C$3:$H$56,4,FALSE) -> 100 | J24: =ROUNDUP((G24/I24),0) -> 1 | K24: =IF(J24*0.55>1.2,J24*0.55,1.2) -> 1.2 | L24: =VLOOKUP(E24,'NPT 011 - Anexo A - Tabela 1'!$C$3:$H$56,5,FALSE) -> 60 | M24: =ROUNDUP((G24/L24),0) -> 1 | N24: =IF(M24*0.55>1.2,M24*0.55,1.2) -> 1.2 | O24: =VLOOKUP(E24,'NPT 011 - Anexo A - Tabela 1'!$C$3:$H$56,6,FALSE) -> 100 | P24: =ROUNDUP((G24/O24),0) -> 1 | Q24: =IF(P24*0.55>0.8,P24*0.55,0.8) -> 0.8
C25: Produção | D25: 182 | E25: I-2 | F25: =VLOOKUP(E25,'NPT 011 - Anexo A - Tabela 1'!$C$9:$H$62,2,FALSE) -> Uma pessoa por 10,0 m² de área | G25: =ROUNDUP(IF(VLOOKUP(E25,'NPT 011 - Anexo A - Tabela 1'!$C$3:$E$56,3,FALSE)=0,"Ver índice de cálculo",D25/VLOOKUP(E25,'NPT 011 - Anexo A - Tabela 1'!$C$3:$E$56,3,FALSE)),0) -> 19 | H25: 35 | I25: =VLOOKUP(E25,'NPT 011 - Anexo A - Tabela 1'!$C$3:$H$56,4,FALSE) -> 100 | J25: =ROUNDUP((G25/I25),0) -> 1 | K25: =IF(J25*0.55>1.2,J25*0.55,1.2) -> 1.2 | L25: =VLOOKUP(E25,'NPT 011 - Anexo A - Tabela 1'!$C$3:$H$56,5,FALSE) -> 60 | M25: =ROUNDUP((G25/L25),0) -> 1 | N25: =IF(M25*0.55>1.2,M25*0.55,1.2) -> 1.2 | O25: =VLOOKUP(E25,'NPT 011 - Anexo A - Tabela 1'!$C$3:$H$56,6,FALSE) -> 100 | P25: =ROUNDUP((G25/O25),0) -> 1 | Q25: =IF(P25*0.55>0.8,P25*0.55,0.8) -> 0.8
C26: Produção | D26: 183 | E26: I-3 | F26: =VLOOKUP(E26,'NPT 011 - Anexo A - Tabela 1'!$C$9:$H$62,2,FALSE) -> Uma pessoa por 10,0 m² de área | G26: =ROUNDUP(IF(VLOOKUP(E26,'NPT 011 - Anexo A - Tabela 1'!$C$3:$E$56,3,FALSE)=0,"Ver índice de cálculo",D26/VLOOKUP(E26,'NPT 011 - Anexo A - Tabela 1'!$C$3:$E$56,3,FALSE)),0) -> 19 | H26: 35 | I26: =VLOOKUP(E26,'NPT 011 - Anexo A - Tabela 1'!$C$3:$H$56,4,FALSE) -> 100 | J26: =ROUNDUP((G26/I26),0) -> 1 | K26: =IF(J26*0.55>1.2,J26*0.55,1.2) -> 1.2 | L26: =VLOOKUP(E26,'NPT 011 - Anexo A - Tabela 1'!$C$3:$H$56,5,FALSE) -> 60 | M26: =ROUNDUP((G26/L26),0) -> 1 | N26: =IF(M26*0.55>1.2,M26*0.55,1.2) -> 1.2 | O26: =VLOOKUP(E26,'NPT 011 - Anexo A - Tabela 1'!$C$3:$H$56,6,FALSE) -> 100 | P26: =ROUNDUP((G26/O26),0) -> 1 | Q26: =IF(P26*0.55>0.8,P26*0.55,0.8) -> 0.8
C27: aa | D27: 212 | E27: D-1 | F27: =VLOOKUP(E27,'NPT 011 - Anexo A - Tabela 1'!$C$9:$H$62,2,FALSE) -> Uma pessoa por 7,0 m² de área | G27: =ROUNDUP(IF(VLOOKUP(E27,'NPT 011 - Anexo A - Tabela 1'!$C$3:$E$56,3,FALSE)=0,"Ver índice de cálculo",D27/VLOOKUP(E27,'NPT 011 - Anexo A - Tabela 1'!$C$3:$E$56,3,FALSE)),0) -> 31 | H27: 35 | I27: =VLOOKUP(E27,'NPT 011 - Anexo A - Tabela 1'!$C$3:$H$56,4,FALSE) -> 100 | J27: =ROUNDUP((G27/I27),0) -> 1 | K27: =IF(J27*0.55>1.2,J27*0.55,1.2) -> 1.2 | L27: =VLOOKUP(E27,'NPT 011 - Anexo A - Tabela 1'!$C$3:$H$56,5,FALSE) -> 75 | M27: =ROUNDUP((G27/L27),0) -> 1 | N27: =IF(M27*0.55>1.2,M27*0.55,1.2) -> 1.2 | O27: =VLOOKUP(E27,'NPT 011 - Anexo A - Tabela 1'!$C$3:$H$56,6,FALSE) -> 100 | P27: =ROUNDUP((G27/O27),0) -> 1 | Q27: =IF(P27*0.55>0.8,P27*0.55,0.8) -> 0.8
C28: Oficina | D28: 37.15 | E28: G-4 | F28: =VLOOKUP(E28,'NPT 011 - Anexo A - Tabela 1'!$C$9:$H$62,2,FALSE) -> Uma pessoa por 20,0 m² de área | G28: =ROUNDUP(IF(VLOOKUP(E28,'NPT 011 - Anexo A - Tabela 1'!$C$3:$E$56,3,FALSE)=0,"Ver índice de cálculo",D28/VLOOKUP(E28,'NPT 011 - Anexo A - Tabela 1'!$C$3:$E$56,3,FALSE)),0) -> 2 | H28: 28 | I28: =VLOOKUP(E28,'NPT 011 - Anexo A - Tabela 1'!$C$3:$H$56,4,FALSE) -> 100 | J28: =ROUNDUP((G28/I28),0) -> 1 | K28: =IF(J28*0.55>1.2,J28*0.55,1.2) -> 1.2 | L28: =VLOOKUP(E28,'NPT 011 - Anexo A - Tabela 1'!$C$3:$H$56,5,FALSE) -> 60 | M28: =ROUNDUP((G28/L28),0) -> 1 | N28: =IF(M28*0.55>1.2,M28*0.55,1.2) -> 1.2 | O28: =VLOOKUP(E28,'NPT 011 - Anexo A - Tabela 1'!$C$3:$H$56,6,FALSE) -> 100 | P28: =ROUNDUP((G28/O28),0) -> 1 | Q28: =IF(P28*0.55>0.8,P28*0.55,0.8) -> 0.8
C29: Refeitório | D29: 29.25 | E29: F-8 | F29: =VLOOKUP(E29,'NPT 011 - Anexo A - Tabela 1'!$C$9:$H$62,2,FALSE) -> Uma pessoa por 1,0 m² de área (O) | G29: =ROUNDUP(IF(VLOOKUP(E29,'NPT 011 - Anexo A - Tabela 1'!$C$3:$E$56,3,FALSE)=0,"Ver índice de cálculo",D29/VLOOKUP(E29,'NPT 011 - Anexo A - Tabela 1'!$C$3:$E$56,3,FALSE)),0) -> 30 | H29: 28 | I29: =VLOOKUP(E29,'NPT 011 - Anexo A - Tabela 1'!$C$3:$H$56,4,FALSE) -> 100 | J29: =ROUNDUP((G29/I29),0) -> 1 | K29: =IF(J29*0.55>1.2,J29*0.55,1.2) -> 1.2 | L29: =VLOOKUP(E29,'NPT 011 - Anexo A - Tabela 1'!$C$3:$H$56,5,FALSE) -> 75 | M29: =ROUNDUP((G29/L29),0) -> 1 | N29: =IF(M29*0.55>1.2,M29*0.55,1.2) -> 1.2 | O29: =VLOOKUP(E29,'NPT 011 - Anexo A - Tabela 1'!$C$3:$H$56,6,FALSE) -> 100 | P29: =ROUNDUP((G29/O29),0) -> 1 | Q29: =IF(P29*0.55>0.8,P29*0.55,0.8) -> 0.8
C30: TOTAL | E30: I-2 | F30: - | G30: =SUM(G25:G29) -> 101 | H30: - | I30: =VLOOKUP(E30,'NPT 011 - Anexo A - Tabela 1'!$C$3:$H$56,4,FALSE) -> 100 | J30: =ROUNDUP((G30/I30),0) -> 2 | K30: =IF(J30*0.55>1.2,J30*0.55,1.2) -> 1.2 | L30: =VLOOKUP(E30,'NPT 011 - Anexo A - Tabela 1'!$C$3:$H$56,5,FALSE) -> 60 | M30: =ROUNDUP((G30/L30),0) -> 2 | N30: =IF(M30*0.55>1.2,M30*0.55,1.2) -> 1.2 | O30: =VLOOKUP(E30,'NPT 011 - Anexo A - Tabela 1'!$C$3:$H$56,6,FALSE) -> 100 | P30: =ROUNDUP((G30/O30),0) -> 2 | Q30: =IF(P30*0.55>0.8,P30*0.55,0.8) -> 1.1
B31: TOTAL | G31: =G22+G30 -> 160 | H31: Pessoas

Sheet CLASSIFICAÇÃO
B2: Grupo | C2: Tipo | D2: Classificação
B3: D | C3: Classe de uso/ocupação | D3: Serviço Profissional
C4: Divisão | D4: D-1
C5: Descrição | D5: Local para prestação de serviço profissional ou condução de negócios
B6: F | C6: Classe de uso/ocupação | D6: Local de Reunião de Público
C7: Divisão | D7: F-8
C8: Descrição | D8: Local para refeição
B9: G | C9: Classe de uso/ocupação | D9: Serviço automotivo e assemelhados
C10: Divisão | D10: G-4
C11: Descrição | D11: Serviço de conservação, manutenção e reparos
B12: I | C12: Classe de uso/ocupação | D12: Industrial
C13: Divisão | D13: I-2
C14: Descrição | D14: Locais onde as atividades exercidas e os materiais utilizados apresentam médio potencial de incêndio (carga de incêndio acima de 300 MJ/m² e até 1200 MJ/m²)
B15: J | C15: Classe de uso/ocupação | D15: Depósito
C16: Divisão | D16: J-3
C17: Descrição | D17: Depósitos com carga de incêndio acima de 300 MJ/m² até 1200 MJ/m²)
